Workbook
Name Hallazgo: 'H1'!$B$6
Name Recurso: 'H1'!$B$4

Sheet LHCQ
A1: LISTA DE CHEQUEO ACCESIBILIDAD DISEÑO WEB: CRITERIOS GENERALES - WCAG 2.1
A2: CF1 - Estructuración de medición de variables ambientales en agroecosistemas
A4: Nivel de conformidad: AA El objetivo principal de la presente lista de chequeo es proporcionar una herramienta estructurada que permita a los evaluadores, diseñadores y desarrolladores identificar los problemas de accesibilidad más frecuentes dentro del proceso de producción de los Recursos Educativos Digitales SENA con el fin de aplicar correctivos, promover buenas prácticas y mejorar la calidad de los contenidos producidos, garantizando una buena experiencia de uso para todos los usuarios.
B5: CUMPLE | C5: NO CUMPLE
A6: 1. Contenido no textual (WCAG 2.1 - Criterio 1.1.1) | B6: x
A7: Todo contenido no textual que se presenta al usuario tiene una alternativa textual que cumple el mismo propósito, excepto en las situaciones enumeradas a continuación: videos, actividadas didácticas e imágenes decorativas.
A8: Consideraciones:
A9: Para el caso específico de las imágenes que presentan información al usuario se debe hacer uso del atributo alt que está definido en un conjunto de etiquetas para permitir proporcionar un texto equivalente.
A10: Las imágenes que no transmitan información sean decorativas o con el contenido ya presente como texto, se ofrecerán con el texto alternativo vacío (alt="") o aplicadas como fondos de imagen CSS.
A12: 2. Características sensoriales (WCAG 2.1 - Criterio 1.3.3) | B12: x
A13: Las instrucciones no dependen de la forma, tamaño o ubicación visual (por ejemplo, "Haga clic en el icono cuadrado para continuar" o "Las instrucciones están en la columna de la derecha").
A15: 3. Uso del color (WCAG 2.1 - Criterio 1.4.1) | B15: x
A16: El color no se usa como único medio visual para transmitir la información, indicar una acción, solicitar una respuesta o distinguir un elemento visual.
A17: Ejemplo:
A18: Los enlaces deben distinguirse de los elementos y texto que les rodean. Si utiliza el color para diferenciar los enlaces, use una forma adicional para distinguirlos (por ejemplo, subrayarlos).
A20: 4. Contraste mínimo (WCAG 2.1 - Criterio 1.4.3) | B20: x
A21: La presentación visual de texto e imágenes de texto tiene una relación de contraste de, al menos, 4.5:1
A22: Excepciones:
A23: En textos grandes (de más de 18 puntos o 14 puntos en negrita), incluidas las imágenes de texto, donde la relación de contraste debe ser de al menos 3:1.
A24: Excepto en los textos, o las imágenes de texto, que forman parte de un componente de la interfaz de usuario inactivo, que son meramente decorativos o que no son visibles, que no tienen un requisito mínimo de contraste.
A26: 5. Reajuste de elementos (WCAG 2.1 - Criterio 1.4.10) | B26: x
A27: El contenido se puede presentar sin perder información o funcionalidad, y sin requerir scroll en dos dimensiones, excepto para aquellas partes del contenido que requieren ese desplazamiento (imágenes, mapas, diagramas, videos, presentaciones, tablas, entre otros.) Los sitios y aplicaciones web deben admitir orientación vertical y horizontal, asegurándose de que el contenido y la funcionalidad estén disponibles en cada orientación.
A29: 6. Contraste no textual (WCAG 2.1 - Criterio 1.4.11) | B29: x
A30: La presentación visual de los objetos gráficos (partes de los gráficos necesarios para comprender el contenido, excepto cuando una presentación concreta sea esencial para la información mostrada) tiene una ratio de contraste de la menos 3:1 con los colores adyacentes.
A31: Consideraciones:
A32: Aplica a: iconos que no van con texto; gráficos, por ejemplo, cada una de sus líneas; el borde o límites visuales de un campo de formulario o botón, siempre que no estuviera disabled; el indicador visual del valor actual en un control deslizante; el indicador del foco.
A34: 7. Propósito de los enlaces (WCAG 2.1 - Criterio 2.4.4) | B34: x
A35: Los enlaces y botones presentes en el sitio web son lo suficientemente descriptivos como para identificar su propósito.
A36: Consideraciones:
A37: Siempre que no sean ambiguos para los usuarios en general, los enlaces (o botones de imagen en un formulario, o zonas activas en un mapa de imagen) serán lo suficientemente descriptivos como para identificar su propósito (objetivo) directamente desde el texto enlazado o, en su caso, desde el enlace en su contexto (por ejemplo, en los párrafos que lo rodean, elementos de una lista, celdas o encabezados en una tabla, etc.).
A39: 8. Navegación coherente (WCAG 2.1 - Criterio 3.2.3) | B39: x
A40: Los mecanismos de navegación que se repiten en múltiples páginas web dentro de un conjunto de páginas web aparecen siempre en el mismo orden relativo cada vez que se repiten, a menos que el cambio sea provocado por el propio usuario.
A42: 9. Identificación consistente (WCAG 2.1 - Criterio 3.2.4) | B42: x
A43: Los componentes que tienen la misma funcionalidad dentro de un conjunto de páginas web son identificados de manera consistente.
A44: Consideraciones:
A45: Los componentes web que se repiten dentro del contenido deberán ser consistentes en su funcionalidad y estilo (color - forma - estados - texto alternativos).

Sheet RESUMEN
A1: LISTA DE CHEQUEO VALIDACIÓN RED
A2: =LHCQ!A2 -> CF1 - Estructuración de medición de variables ambientales en agroecosistemas
F3: REALIZACIÓN DE LOS AJUSTES | J3: REVISION DE LOS AJUSTES
A4: No Registro | B4: Recurso | C4: Descripción del hallazgo | D4: Tipo de hallazgo | E4: Ruta | F4: Ajuste completo | G4: Ajuste parcial | H4: No se hizo el ajuste | I4: Observaciones | J4: AJUSTE REALIZADO | K4: CON PENDENTES | L4: AJUSTE NO REALIZADO | M4: OBSERVACIONES
A5: ='H1'!$B$3 -> 1 | B5: ='H1'!$B$4 -> XD | C5: ='H1'!$B$5 -> Por la extensión del contenido no se recomienda utilizar el componente de tarjeta, se recomienda utlizar acordeones o pestañas | D5: ='H1'!$B$6 -> Diseño Web | E5: ='H1'!$B$7 -> Tema 1 | F5: ='H1'!$D$5 -> x | G5: ='H1'!$E$5 -> 0 | H5: ='H1'!$F$5 -> 0 | I5: ='H1'!$G$5 -> 0 | J5: ='H1'!$D$9 -> 0 | K5: ='H1'!$E$9 -> 0 | L5: ='H1'!$F$9 -> 0 | M5: ='H1'!$G$9 -> 0
A6: ='H2'!$B$3 -> 2 | B6: ='H2'!$B$4 -> XD | C6: ='H2'!$B$5 -> Por la extensión del contenido no se recomienda utilizar el componente de tarjeta, se recomienda utlizar acordeones o pestañas | D6: ='H2'!$B$6 -> Diseño Web | E6: ='H2'!$B$7 -> Tema 1 | F6: ='H2'!$D$5 -> x | G6: ='H2'!$E$5 -> 0 | H6: ='H2'!$F$5 -> 0 | I6: ='H2'!$G$5 -> 0 | J6: ='H2'!$D$9 -> 0 | K6: ='H2'!$E$9 -> 0 | L6: ='H2'!$F$9 -> 0 | M6: ='H2'!$G$9 -> 0
A7: ='H3'!$B$3 -> 3 | B7: ='H3'!$B$4 -> XD | C7: ='H3'!$B$5 -> Eliminar el punto final del numeral de todos los títulos de segundo nivel | D7: ='H3'!$B$6 -> Diseño Web | E7: ='H3'!$B$7 -> Tema 1 | F7: ='H3'!$D$5 -> x | G7: ='H3'!$E$5 -> 0 | H7: ='H3'!$F$5 -> 0 | I7: ='H3'!$G$5 -> 0 | J7: ='H3'!$D$9 -> 0 | K7: ='H3'!$E$9 -> 0 | L7: ='H3'!$F$9 -> 0 | M7: ='H3'!$G$9 -> 0
A8: ='H4'!$B$3 -> 4 | B8: ='H4'!$B$4 -> XD | C8: ='H4'!$B$5 -> Quitar itálica de las palabras señaladas | D8: ='H4'!$B$6 -> Diseñó Web | E8: ='H4'!$B$7 -> Tema 1 | F8: ='H4'!$D$5 -> x | G8: ='H4'!$E$5 -> 0 | H8: ='H4'!$F$5 -> 0 | I8: ='H4'!$G$5 -> 0 | J8: ='H4'!$D$9 -> 0 | K8: ='H4'!$E$9 -> 0 | L8: ='H4'!$F$9 -> 0 | M8: ='H4'!$G$9 -> 0
A9: ='H5'!$B$3 -> 5 | B9: ='H5'!$B$4 -> 0 | C9: ='H5'!$B$5 -> 0 | D9: ='H5'!$B$6 -> 0 | E9: ='H5'!$B$7 -> 0 | F9: ='H5'!$D$5 -> 0 | G9: ='H5'!$E$5 -> 0 | H9: ='H5'!$F$5 -> 0 | I9: ='H5'!$G$5 -> 0 | J9: ='H5'!$D$9 -> 0 | K9: ='H5'!$E$9 -> 0 | L9: ='H5'!$F$9 -> 0 | M9: ='H5'!$G$9 -> 0
A10: ='H6'!$B$3 -> 6 | B10: ='H6'!$B$4 -> 0 | C10: ='H6'!$B$5 -> 0 | D10: ='H6'!$B$6 -> 0 | E10: ='H6'!$B$7 -> 0 | F10: ='H6'!$D$5 -> 0 | G10: ='H6'!$E$5 -> 0 | H10: ='H6'!$F$5 -> 0 | I10: ='H6'!$G$5 -> 0 | J10: ='H6'!$D$9 -> 0 | K10: ='H6'!$E$9 -> 0 | L10: ='H6'!$F$9 -> 0 | M10: ='H6'!$G$9 -> 0
A11: ='H7'!$B$3 -> 7 | B11: ='H7'!$B$4 -> 0 | C11: ='H7'!$B$5 -> 0 | D11: ='H7'!$B$6 -> 0 | E11: ='H7'!$B$7 -> 0 | F11: ='H7'!$D$5 -> 0 | G11: ='H7'!$E$5 -> 0 | H11: ='H7'!$F$5 -> 0 | I11: ='H7'!$G$5 -> 0 | J11: ='H7'!$D$9 -> 0 | K11: ='H7'!$E$9 -> 0 | L11: ='H7'!$F$9 -> 0 | M11: ='H7'!$G$9 -> 0
A12: ='H8'!$B$3 -> 8 | B12: ='H8'!$B$4 -> 0 | C12: ='H8'!$B$5 -> 0 | D12: ='H8'!$B$6 -> 0 | E12: ='H8'!$B$7 -> 0 | F12: ='H8'!$D$5 -> 0 | G12: ='H8'!$E$5 -> 0 | H12: ='H8'!$F$5 -> 0 | I12: ='H8'!$G$5 -> 0 | J12: ='H8'!$D$9 -> 0 | K12: ='H8'!$E$9 -> 0 | L12: ='H8'!$F$9 -> 0 | M12: ='H8'!$G$9 -> 0
A13: ='H9'!$B$3 -> 9 | B13: ='H9'!$B$4 -> 0 | C13: ='H9'!$B$5 -> 0 | D13: ='H9'!$B$6 -> 0 | E13: ='H9'!$B$7 -> 0 | F13: ='H9'!$D$5 -> 0 | G13: ='H9'!$E$5 -> 0 | H13: ='H9'!$F$5 -> 0 | I13: ='H9'!$G$5 -> 0 | J13: ='H9'!$D$9 -> 0 | K13: ='H9'!$E$9 -> 0 | L13: ='H9'!$F$9 -> 0 | M13: ='H9'!$G$9 -> 0
A14: ='H10'!$B$3 -> 10 | B14: ='H10'!$B$4 -> 0 | C14: ='H10'!$B$5 -> 0 | D14: ='H10'!$B$6 -> 0 | E14: ='H10'!$B$7 -> 0 | F14: ='H10'!$D$5 -> 0 | G14: ='H10'!$E$5 -> 0 | H14: ='H10'!$F$5 -> 0 | I14: ='H10'!$G$5 -> 0 | J14: ='H10'!$D$9 -> 0 | K14: ='H10'!$E$9 -> 0 | L14: ='H10'!$F$9 -> 0 | M14: ='H10'!$G$9 -> 0
A15: ='H11'!$B$3 -> 11 | B15: ='H11'!$B$4 -> 0 | C15: ='H11'!$B$5 -> 0 | D15: ='H11'!$B$6 -> 0 | E15: ='H11'!$B$7 -> 0 | F15: ='H11'!$D$5 -> 0 | G15: ='H11'!$E$5 -> 0 | H15: ='H11'!$F$5 -> 0 | I15: ='H11'!$G$5 -> 0 | J15: ='H11'!$D$9 -> 0 | K15: ='H11'!$E$9 -> 0 | L15: ='H11'!$F$9 -> 0 | M15: ='H11'!$G$9 -> 0
A16: ='H12'!$B$3 -> 12 | B16: ='H12'!$B$4 -> 0 | C16: ='H12'!$B$5 -> 0 | D16: ='H12'!$B$6 -> 0 | E16: ='H12'!$B$7 -> 0 | F16: ='H12'!$D$5 -> 0 | G16: ='H12'!$E$5 -> 0 | H16: ='H12'!$F$5 -> 0 | I16: ='H12'!$G$5 -> 0 | J16: ='H12'!$D$9 -> 0 | K16: ='H12'!$E$9 -> 0 | L16: ='H12'!$F$9 -> 0 | M16: ='H12'!$G$9 -> 0
A17: ='H13'!$B$3 -> 13 | B17: ='H13'!$B$4 -> 0 | C17: ='H13'!$B$5 -> 0 | D17: ='H13'!$B$6 -> 0 | E17: ='H13'!$B$7 -> 0 | F17: ='H13'!$D$5 -> 0 | G17: ='H13'!$E$5 -> 0 | H17: ='H13'!$F$5 -> 0 | I17: ='H13'!$G$5 -> 0 | J17: ='H13'!$D$9 -> 0 | K17: ='H13'!$E$9 -> 0 | L17: ='H13'!$F$9 -> 0 | M17: ='H13'!$G$9 -> 0
A18: ='H14'!$B$3 -> 14 | B18: ='H14'!$B$4 -> 0 | C18: ='H14'!$B$5 -> 0 | D18: ='H14'!$B$6 -> 0 | E18: ='H14'!$B$7 -> 0 | F18: ='H14'!$D$5 -> 0 | G18: ='H14'!$E$5 -> 0 | H18: ='H14'!$F$5 -> 0 | I18: ='H14'!$G$5 -> 0 | J18: ='H14'!$D$9 -> 0 | K18: ='H14'!$E$9 -> 0 | L18: ='H14'!$F$9 -> 0 | M18: ='H14'!$G$9 -> 0
A19: ='H15'!$B$3 -> 15 | B19: ='H15'!$B$4 -> 0 | C19: ='H15'!$B$5 -> 0 | D19: ='H15'!$B$6 -> 0 | E19: ='H15'!$B$7 -> 0 | F19: ='H15'!$D$5 -> 0 | G19: ='H15'!$E$5 -> 0 | H19: ='H15'!$F$5 -> 0 | I19: ='H15'!$G$5 -> 0 | J19: ='H15'!$D$9 -> 0 | K19: ='H15'!$E$9 -> 0 | L19: ='H15'!$F$9 -> 0 | M19: ='H15'!$G$9 -> 0
A20: ='H16'!$B$3 -> 16 | B20: ='H16'!$B$4 -> 0 | C20: ='H16'!$B$5 -> 0 | D20: ='H16'!$B$6 -> 0 | E20: ='H16'!$B$7 -> 0 | F20: ='H16'!$D$5 -> 0 | G20: ='H16'!$E$5 -> 0 | H20: ='H16'!$F$5 -> 0 | I20: ='H16'!$G$5 -> 0 | J20: ='H16'!$D$9 -> 0 | K20: ='H16'!$E$9 -> 0 | L20: ='H16'!$F$9 -> 0 | M20: ='H16'!$G$9 -> 0
A21: ='H17'!$B$3 -> 17 | B21: ='H17'!$B$4 -> 0 | C21: ='H17'!$B$5 -> 0 | D21: ='H17'!$B$6 -> 0 | E21: ='H17'!$B$7 -> 0 | F21: ='H17'!$D$5 -> 0 | G21: ='H17'!$E$5 -> 0 | H21: ='H17'!$F$5 -> 0 | I21: ='H17'!$G$5 -> 0 | J21: ='H17'!$D$9 -> 0 | K21: ='H17'!$E$9 -> 0 | L21: ='H17'!$F$9 -> 0 | M21: ='H17'!$G$9 -> 0
A22: ='H18'!$B$3 -> 18 | B22: ='H18'!$B$4 -> 0 | C22: ='H18'!$B$5 -> 0 | D22: ='H18'!$B$6 -> 0 | E22: ='H18'!$B$7 -> 0 | F22: ='H18'!$D$5 -> 0 | G22: ='H18'!$E$5 -> 0 | H22: ='H18'!$F$5 -> 0 | I22: ='H18'!$G$5 -> 0 | J22: ='H18'!$D$9 -> 0 | K22: ='H18'!$E$9 -> 0 | L22: ='H18'!$F$9 -> 0 | M22: ='H18'!$G$9 -> 0
A23: ='H19'!$B$3 -> 19 | B23: ='H19'!$B$4 -> 0 | C23: ='H19'!$B$5 -> 0 | D23: ='H19'!$B$6 -> 0 | E23: ='H19'!$B$7 -> 0 | F23: ='H19'!$D$5 -> 0 | G23: ='H19'!$E$5 -> 0 | H23: ='H19'!$F$5 -> 0 | I23: ='H19'!$G$5 -> 0 | J23: ='H19'!$D$9 -> 0 | K23: ='H19'!$E$9 -> 0 | L23: ='H19'!$F$9 -> 0 | M23: ='H19'!$G$9 -> 0
A24: ='H20'!$B$3 -> 20 | B24: ='H20'!$B$4 -> 0 | C24: ='H20'!$B$5 -> 0 | D24: ='H20'!$B$6 -> 0 | E24: ='H20'!$B$7 -> 0 | F24: ='H20'!$D$5 -> 0 | G24: ='H20'!$E$5 -> 0 | H24: ='H20'!$F$5 -> 0 | I24: ='H20'!$G$5 -> 0 | J24: ='H20'!$D$9 -> 0 | K24: ='H20'!$E$9 -> 0 | L24: ='H20'!$F$9 -> 0 | M24: ='H20'!$G$9 -> 0
A25: ='H21'!$B$3 -> 21 | B25: ='H21'!$B$4 -> 0 | C25: ='H21'!$B$5 -> 0 | D25: ='H21'!$B$6 -> 0 | E25: ='H21'!$B$7 -> 0 | F25: ='H21'!$D$5 -> 0 | G25: ='H21'!$E$5 -> 0 | H25: ='H21'!$F$5 -> 0 | I25: ='H21'!$G$5 -> 0 | J25: ='H21'!$D$9 -> 0 | K25: ='H21'!$E$9 -> 0 | L25: ='H21'!$F$9 -> 0 | M25: ='H21'!$G$9 -> 0
A26: ='H22'!$B$3 -> 22 | B26: ='H22'!$B$4 -> 0 | C26: ='H22'!$B$5 -> 0 | D26: ='H22'!$B$6 -> 0 | E26: ='H22'!$B$7 -> 0 | F26: ='H22'!$D$5 -> 0 | G26: ='H22'!$E$5 -> 0 | H26: ='H22'!$F$5 -> 0 | I26: ='H22'!$G$5 -> 0 | J26: ='H22'!$D$9 -> 0 | K26: ='H22'!$E$9 -> 0 | L26: ='H22'!$F$9 -> 0 | M26: ='H22'!$G$9 -> 0
A27: ='H23'!$B$3 -> 23 | B27: ='H23'!$B$4 -> 0 | C27: ='H23'!$B$5 -> 0 | D27: ='H23'!$B$6 -> 0 | E27: ='H23'!$B$7 -> 0 | F27: ='H23'!$D$5 -> 0 | G27: ='H23'!$E$5 -> 0 | H27: ='H23'!$F$5 -> 0 | I27: ='H23'!$G$5 -> 0 | J27: ='H23'!$D$9 -> 0 | K27: ='H23'!$E$9 -> 0 | L27: ='H23'!$F$9 -> 0 | M27: ='H23'!$G$9 -> 0
A28: ='H24'!$B$3 -> 24 | B28: ='H24'!$B$4 -> 0 | C28: ='H24'!$B$5 -> 0 | D28: ='H24'!$B$6 -> 0 | E28: ='H24'!$B$7 -> 0 | F28: ='H24'!$D$5 -> 0 | G28: ='H24'!$E$5 -> 0 | H28: ='H24'!$F$5 -> 0 | I28: ='H24'!$G$5 -> 0 | J28: ='H24'!$D$9 -> 0 | K28: ='H24'!$E$9 -> 0 | L28: ='H24'!$F$9 -> 0 | M28: ='H24'!$G$9 -> 0
A29: ='H25'!$B$3 -> 25 | B29: ='H25'!$B$4 -> 0 | C29: ='H25'!$B$5 -> 0 | D29: ='H25'!$B$6 -> 0 | E29: ='H25'!$B$7 -> 0 | F29: ='H25'!$D$5 -> 0 | G29: ='H25'!$E$5 -> 0 | H29: ='H25'!$F$5 -> 0 | I29: ='H25'!$G$5 -> 0 | J29: ='H25'!$D$9 -> 0 | K29: ='H25'!$E$9 -> 0 | L29: ='H25'!$F$9 -> 0 | M29: ='H25'!$G$9 -> 0
A30: ='H26'!$B$3 -> 26 | B30: ='H26'!$B$4 -> 0 | C30: ='H26'!$B$5 -> 0 | D30: ='H26'!$B$6 -> 0 | E30: ='H26'!$B$7 -> 0 | F30: ='H26'!$D$5 -> 0 | G30: ='H26'!$E$5 -> 0 | H30: ='H26'!$F$5 -> 0 | I30: ='H26'!$G$5 -> 0 | J30: ='H26'!$D$9 -> 0 | K30: ='H26'!$E$9 -> 0 | L30: ='H26'!$F$9 -> 0 | M30: ='H26'!$G$9 -> 0
A31: ='H27'!$B$3 -> 27 | B31: ='H27'!$B$4 -> 0 | C31: ='H27'!$B$5 -> 0 | D31: ='H27'!$B$6 -> 0 | E31: ='H27'!$B$7 -> 0 | F31: ='H27'!$D$5 -> 0 | G31: ='H27'!$E$5 -> 0 | H31: ='H27'!$F$5 -> 0 | I31: ='H27'!$G$5 -> 0 | J31: ='H27'!$D$9 -> 0 | K31: ='H27'!$E$9 -> 0 | L31: ='H27'!$F$9 -> 0 | M31: ='H27'!$G$9 -> 0
A32: ='H28'!$B$3 -> 28 | B32: ='H28'!$B$4 -> 0 | C32: ='H28'!$B$5 -> 0 | D32: ='H28'!$B$6 -> 0 | E32: ='H28'!$B$7 -> 0 | F32: ='H28'!$D$5 -> 0 | G32: ='H28'!$E$5 -> 0 | H32: ='H28'!$F$5 -> 0 | I32: ='H28'!$G$5 -> 0 | J32: ='H28'!$D$9 -> 0 | K32: ='H28'!$E$9 -> 0 | L32: ='H28'!$F$9 -> 0 | M32: ='H28'!$G$9 -> 0
A33: ='H29'!$B$3 -> 29 | B33: ='H29'!$B$4 -> 0 | C33: ='H29'!$B$5 -> 0 | D33: ='H29'!$B$6 -> 0 | E33: ='H29'!$B$7 -> 0 | F33: ='H29'!$D$5 -> 0 | G33: ='H29'!$E$5 -> 0 | H33: ='H29'!$F$5 -> 0 | I33: ='H29'!$G$5 -> 0 | J33: ='H29'!$D$9 -> 0 | K33: ='H29'!$E$9 -> 0 | L33: ='H29'!$F$9 -> 0 | M33: ='H29'!$G$9 -> 0
A34: ='H30'!$B$3 -> 30 | B34: ='H30'!$B$4 -> 0 | C34: ='H30'!$B$5 -> 0 | D34: ='H30'!$B$6 -> 0 | E34: ='H30'!$B$7 -> 0 | F34: ='H30'!$D$5 -> 0 | G34: ='H30'!$E$5 -> 0 | H34: ='H30'!$F$5 -> 0 | I34: ='H30'!$G$5 -> 0 | J34: ='H30'!$D$9 -> 0 | K34: ='H30'!$E$9 -> 0 | L34: ='H30'!$F$9 -> 0 | M34: ='H30'!$G$9 -> 0
A35: ='H31'!$B$3 -> 31 | B35: ='H31'!$B$4 -> 0 | C35: ='H31'!$B$5 -> 0 | D35: ='H31'!$B$6 -> 0 | E35: ='H31'!$B$7 -> 0 | F35: ='H31'!$D$5 -> 0 | G35: ='H31'!$E$5 -> 0 | H35: ='H31'!$F$5 -> 0 | I35: ='H31'!$G$5 -> 0 | J35: ='H31'!$D$9 -> 0 | K35: ='H31'!$E$9 -> 0 | L35: ='H31'!$F$9 -> 0 | M35: ='H31'!$G$9 -> 0
A36: ='H32'!$B$3 -> 32 | B36: ='H32'!$B$4 -> 0 | C36: ='H32'!$B$5 -> 0 | D36: ='H32'!$B$6 -> 0 | E36: ='H32'!$B$7 -> 0 | F36: ='H32'!$D$5 -> 0 | G36: ='H32'!$E$5 -> 0 | H36: ='H32'!$F$5 -> 0 | I36: ='H32'!$G$5 -> 0 | J36: ='H32'!$D$9 -> 0 | K36: ='H32'!$E$9 -> 0 | L36: ='H32'!$F$9 -> 0 | M36: ='H32'!$G$9 -> 0
A37: ='H33'!$B$3 -> 33 | B37: ='H33'!$B$4 -> 0 | C37: ='H33'!$B$5 -> 0 | D37: ='H33'!$B$6 -> 0 | E37: ='H33'!$B$7 -> 0 | F37: ='H33'!$D$5 -> 0 | G37: ='H33'!$E$5 -> 0 | H37: ='H33'!$F$5 -> 0 | I37: ='H33'!$G$5 -> 0 | J37: ='H33'!$D$9 -> 0 | K37: ='H33'!$E$9 -> 0 | L37: ='H33'!$F$9 -> 0 | M37: ='H33'!$G$9 -> 0
A38: ='H34'!$B$3 -> 34 | B38: ='H34'!$B$4 -> 0 | C38: ='H34'!$B$5 -> 0 | D38: ='H34'!$B$6 -> 0 | E38: ='H34'!$B$7 -> 0 | F38: ='H34'!$D$5 -> 0 | G38: ='H34'!$E$5 -> 0 | H38: ='H34'!$F$5 -> 0 | I38: ='H34'!$G$5 -> 0 | J38: ='H34'!$D$9 -> 0 | K38: ='H34'!$E$9 -> 0 | L38: ='H34'!$F$9 -> 0 | M38: ='H34'!$G$9 -> 0
A39: ='H35'!$B$3 -> 35 | B39: ='H35'!$B$4 -> 0 | C39: ='H35'!$B$5 -> 0 | D39: ='H35'!$B$6 -> 0 | E39: ='H35'!$B$7 -> 0 | F39: ='H35'!$D$5 -> 0 | G39: ='H35'!$E$5 -> 0 | H39: ='H35'!$F$5 -> 0 | I39: ='H35'!$G$5 -> 0 | J39: ='H35'!$D$9 -> 0 | K39: ='H35'!$E$9 -> 0 | L39: ='H35'!$F$9 -> 0 | M39: ='H35'!$G$9 -> 0
A40: ='H36'!$B$3 -> 36 | B40: ='H36'!$B$4 -> 0 | C40: ='H36'!$B$5 -> 0 | D40: ='H36'!$B$6 -> 0 | E40: ='H36'!$B$7 -> 0 | F40: ='H36'!$D$5 -> 0 | G40: ='H36'!$E$5 -> 0 | H40: ='H36'!$F$5 -> 0 | I40: ='H36'!$G$5 -> 0 | J40: ='H36'!$D$9 -> 0 | K40: ='H36'!$E$9 -> 0 | L40: ='H36'!$F$9 -> 0 | M40: ='H36'!$G$9 -> 0
...

Sheet H1
A3: N° DE HALLAZGO | B3: 1 | D3: REALIZACION DE LOS AJUSTES
A4: RECURSO | B4: XD | D4: AJUSTE COMPLETO | E4: AJUSTE PARCIAL | F4: NO SE HIZO AJUSTE | G4: OBSERVACIONES
A5: DESCRIPCION DEL HALLAZGO | B5: Por la extensión del contenido no se recomienda utilizar el componente de tarjeta, se recomienda utlizar acordeones o pestañas | D5: x
A6: TIPO DE HALLAZGO | B6: Diseño Web
A7: RUTA | B7: Tema 1 | D7: REVISION DE LOS AJUSTES
D8: AJUSTE REALIZADO | E8: CON PENDENTES | F8: AJUSTE NO REALIZADO | G8: OBSERVACIONES
A13: EVIDENCIAS
A14: DISEÑO XD | C14: GUION

Sheet H2
A3: N° DE HALLAZGO | B3: 2 | D3: REALIZACION DE LOS AJUSTES
A4: RECURSO | B4: =Recurso -> XD | D4: AJUSTE COMPLETO | E4: AJUSTE PARCIAL | F4: NO SE HIZO AJUSTE | G4: OBSERVACIONES
A5: DESCRIPCION DEL HALLAZGO | B5: Por la extensión del contenido no se recomienda utilizar el componente de tarjeta, se recomienda utlizar acordeones o pestañas | D5: x
A6: TIPO DE HALLAZGO | B6: =Hallazgo -> Diseño Web
A7: RUTA | B7: Tema 1 | D7: REVISION DE LOS AJUSTES
D8: AJUSTE REALIZADO | E8: CON PENDENTES | F8: AJUSTE NO REALIZADO | G8: OBSERVACIONES
A13: EVIDENCIAS
A14: DISEÑO XD | C14: GUION

Sheet H3
A3: N° DE HALLAZGO | B3: 3 | D3: REALIZACION DE LOS AJUSTES
A4: RECURSO | B4: =Recurso -> XD | D4: AJUSTE COMPLETO | E4: AJUSTE PARCIAL | F4: NO SE HIZO AJUSTE | G4: OBSERVACIONES
A5: DESCRIPCION DEL HALLAZGO | B5: Eliminar el punto final del numeral de todos los títulos de segundo nivel | D5: x
A6: TIPO DE HALLAZGO | B6: =Hallazgo -> Diseño Web
A7: RUTA | B7: Tema 1 | D7: REVISION DE LOS AJUSTES
D8: AJUSTE REALIZADO | E8: CON PENDENTES | F8: AJUSTE NO REALIZADO | G8: OBSERVACIONES
A13: EVIDENCIAS
A14: DISEÑO XD | C14: GUION

Sheet H4
A3: N° DE HALLAZGO | B3: 4 | D3: REALIZACION DE LOS AJUSTES
A4: RECURSO | B4: XD | D4: AJUSTE COMPLETO | E4: AJUSTE PARCIAL | F4: NO SE HIZO AJUSTE | G4: OBSERVACIONES
A5: DESCRIPCION DEL HALLAZGO | B5: Quitar itálica de las palabras señaladas | D5: x
A6: TIPO DE HALLAZGO | B6: Diseñó Web
A7: RUTA | B7: Tema 1 | D7: REVISION DE LOS AJUSTES
D8: AJUSTE REALIZADO | E8: CON PENDENTES | F8: AJUSTE NO REALIZADO | G8: OBSERVACIONES
A13: EVIDENCIAS
A14: DISEÑO XD | C14: GUION

Sheet H5
A3: N° DE HALLAZGO | B3: 5 | D3: REALIZACION DE LOS AJUSTES
A4: RECURSO | D4: AJUSTE COMPLETO | E4: AJUSTE PARCIAL | F4: NO SE HIZO AJUSTE | G4: OBSERVACIONES
A5: DESCRIPCION DEL HALLAZGO
A6: TIPO DE HALLAZGO
A7: RUTA | D7: REVISION DE LOS AJUSTES
D8: AJUSTE REALIZADO | E8: CON PENDENTES | F8: AJUSTE NO REALIZADO | G8: OBSERVACIONES
A13: EVIDENCIAS
A14: DISEÑO XD | C14: GUION

Sheet H6
A3: N° DE HALLAZGO | B3: 6 | D3: REALIZACION DE LOS AJUSTES
A4: RECURSO | D4: AJUSTE COMPLETO | E4: AJUSTE PARCIAL | F4: NO SE HIZO AJUSTE | G4: OBSERVACIONES
A5: DESCRIPCION DEL HALLAZGO
A6: TIPO DE HALLAZGO
A7: RUTA | D7: REVISION DE LOS AJUSTES
D8: AJUSTE REALIZADO | E8: CON PENDENTES | F8: AJUSTE NO REALIZADO | G8: OBSERVACIONES
A13: EVIDENCIAS
A14: DISEÑO XD | C14: GUION

Sheet H7
A3: N° DE HALLAZGO | B3: 7 | D3: REALIZACION DE LOS AJUSTES
A4: RECURSO | D4: AJUSTE COMPLETO | E4: AJUSTE PARCIAL | F4: NO SE HIZO AJUSTE | G4: OBSERVACIONES
A5: DESCRIPCION DEL HALLAZGO
A6: TIPO DE HALLAZGO
A7: RUTA | D7: REVISION DE LOS AJUSTES
D8: AJUSTE REALIZADO | E8: CON PENDENTES | F8: AJUSTE NO REALIZADO | G8: OBSERVACIONES
A13: EVIDENCIAS
A14: DISEÑO XD | C14: GUION

Sheet H8
A3: N° DE HALLAZGO | B3: 8 | D3: REALIZACION DE LOS AJUSTES
A4: RECURSO | D4: AJUSTE COMPLETO | E4: AJUSTE PARCIAL | F4: NO SE HIZO AJUSTE | G4: OBSERVACIONES
A5: DESCRIPCION DEL HALLAZGO
A6: TIPO DE HALLAZGO
A7: RUTA | D7: REVISION DE LOS AJUSTES
D8: AJUSTE REALIZADO | E8: CON PENDENTES | F8: AJUSTE NO REALIZADO | G8: OBSERVACIONES
A13: EVIDENCIAS
A14: DISEÑO XD | C14: GUION

Sheet H9
A3: N° DE HALLAZGO | B3: 9 | D3: REALIZACION DE LOS AJUSTES
A4: RECURSO | D4: AJUSTE COMPLETO | E4: AJUSTE PARCIAL | F4: NO SE HIZO AJUSTE | G4: OBSERVACIONES
A5: DESCRIPCION DEL HALLAZGO
A6: TIPO DE HALLAZGO
A7: RUTA | D7: REVISION DE LOS AJUSTES
D8: AJUSTE REALIZADO | E8: CON PENDENTES | F8: AJUSTE NO REALIZADO | G8: OBSERVACIONES
A13: EVIDENCIAS
A14: DISEÑO XD | C14: GUION

Sheet H10
A3: N° DE HALLAZGO | B3: 10 | D3: REALIZACION DE LOS AJUSTES
A4: RECURSO | D4: AJUSTE COMPLETO | E4: AJUSTE PARCIAL | F4: NO SE HIZO AJUSTE | G4: OBSERVACIONES
A5: DESCRIPCION DEL HALLAZGO
A6: TIPO DE HALLAZGO
A7: RUTA | D7: REVISION DE LOS AJUSTES
D8: AJUSTE REALIZADO | E8: CON PENDENTES | F8: AJUSTE NO REALIZADO | G8: OBSERVACIONES
A13: EVIDENCIAS
A14: DISEÑO XD | C14: GUION

Sheet H11
A3: N° DE HALLAZGO | B3: 11 | D3: REALIZACION DE LOS AJUSTES
A4: RECURSO | D4: AJUSTE COMPLETO | E4: AJUSTE PARCIAL | F4: NO SE HIZO AJUSTE | G4: OBSERVACIONES
A5: DESCRIPCION DEL HALLAZGO
A6: TIPO DE HALLAZGO
A7: RUTA | D7: REVISION DE LOS AJUSTES
D8: AJUSTE REALIZADO | E8: CON PENDENTES | F8: AJUSTE NO REALIZADO | G8: OBSERVACIONES
A13: EVIDENCIAS
A14: DISEÑO XD | C14: GUION

Sheet H12
A3: N° DE HALLAZGO | B3: 12 | D3: REALIZACION DE LOS AJUSTES
A4: RECURSO | D4: AJUSTE COMPLETO | E4: AJUSTE PARCIAL | F4: NO SE HIZO AJUSTE | G4: OBSERVACIONES
A5: DESCRIPCION DEL HALLAZGO
A6: TIPO DE HALLAZGO
A7: RUTA | D7: REVISION DE LOS AJUSTES
D8: AJUSTE REALIZADO | E8: CON PENDENTES | F8: AJUSTE NO REALIZADO | G8: OBSERVACIONES
A13: EVIDENCIAS
A14: DISEÑO XD | C14: GUION

Sheet H13
A3: N° DE HALLAZGO | B3: 13 | D3: REALIZACION DE LOS AJUSTES
A4: RECURSO | D4: AJUSTE COMPLETO | E4: AJUSTE PARCIAL | F4: NO SE HIZO AJUSTE | G4: OBSERVACIONES
A5: DESCRIPCION DEL HALLAZGO
A6: TIPO DE HALLAZGO
A7: RUTA | D7: REVISION DE LOS AJUSTES
D8: AJUSTE REALIZADO | E8: CON PENDENTES | F8: AJUSTE NO REALIZADO | G8: OBSERVACIONES
A13: EVIDENCIAS
A14: DISEÑO XD | C14: GUION

Sheet H14
A3: N° DE HALLAZGO | B3: 14 | D3: REALIZACION DE LOS AJUSTES
A4: RECURSO | D4: AJUSTE COMPLETO | E4: AJUSTE PARCIAL | F4: NO SE HIZO AJUSTE | G4: OBSERVACIONES
A5: DESCRIPCION DEL HALLAZGO
A6: TIPO DE HALLAZGO
A7: RUTA | D7: REVISION DE LOS AJUSTES
D8: AJUSTE REALIZADO | E8: CON PENDENTES | F8: AJUSTE NO REALIZADO | G8: OBSERVACIONES
A13: EVIDENCIAS
A14: DISEÑO XD | C14: GUION

Sheet H15
A3: N° DE HALLAZGO | B3: 15 | D3: REALIZACION DE LOS AJUSTES
A4: RECURSO | D4: AJUSTE COMPLETO | E4: AJUSTE PARCIAL | F4: NO SE HIZO AJUSTE | G4: OBSERVACIONES
A5: DESCRIPCION DEL HALLAZGO
A6: TIPO DE HALLAZGO
A7: RUTA | D7: REVISION DE LOS AJUSTES
D8: AJUSTE REALIZADO | E8: CON PENDENTES | F8: AJUSTE NO REALIZADO | G8: OBSERVACIONES
A13: EVIDENCIAS
A14: DISEÑO XD | C14: GUION

Sheet H16
A3: N° DE HALLAZGO | B3: 16 | D3: REALIZACION DE LOS AJUSTES
A4: RECURSO | D4: AJUSTE COMPLETO | E4: AJUSTE PARCIAL | F4: NO SE HIZO AJUSTE | G4: OBSERVACIONES
A5: DESCRIPCION DEL HALLAZGO
A6: TIPO DE HALLAZGO
A7: RUTA | D7: REVISION DE LOS AJUSTES
D8: AJUSTE REALIZADO | E8: CON PENDENTES | F8: AJUSTE NO REALIZADO | G8: OBSERVACIONES
A13: EVIDENCIAS
A14: DISEÑO XD | C14: GUION

Sheet H17
A3: N° DE HALLAZGO | B3: 17 | D3: REALIZACION DE LOS AJUSTES
A4: RECURSO | D4: AJUSTE COMPLETO | E4: AJUSTE PARCIAL | F4: NO SE HIZO AJUSTE | G4: OBSERVACIONES
A5: DESCRIPCION DEL HALLAZGO
A6: TIPO DE HALLAZGO
A7: RUTA | D7: REVISION DE LOS AJUSTES
D8: AJUSTE REALIZADO | E8: CON PENDENTES | F8: AJUSTE NO REALIZADO | G8: OBSERVACIONES
A13: EVIDENCIAS
A14: DISEÑO XD | C14: GUION

Sheet H18
A3: N° DE HALLAZGO | B3: 18 | D3: REALIZACION DE LOS AJUSTES
A4: RECURSO | D4: AJUSTE COMPLETO | E4: AJUSTE PARCIAL | F4: NO SE HIZO AJUSTE | G4: OBSERVACIONES
A5: DESCRIPCION DEL HALLAZGO
A6: TIPO DE HALLAZGO
A7: RUTA | D7: REVISION DE LOS AJUSTES
D8: AJUSTE REALIZADO | E8: CON PENDENTES | F8: AJUSTE NO REALIZADO | G8: OBSERVACIONES
A13: EVIDENCIAS
A14: DISEÑO XD | C14: GUION

Sheet H19
A3: N° DE HALLAZGO | B3: 19 | D3: REALIZACION DE LOS AJUSTES
A4: RECURSO | D4: AJUSTE COMPLETO | E4: AJUSTE PARCIAL | F4: NO SE HIZO AJUSTE | G4: OBSERVACIONES
A5: DESCRIPCION DEL HALLAZGO
A6: TIPO DE HALLAZGO
A7: RUTA | D7: REVISION DE LOS AJUSTES
D8: AJUSTE REALIZADO | E8: CON PENDENTES | F8: AJUSTE NO REALIZADO | G8: OBSERVACIONES
A13: EVIDENCIAS
A14: DISEÑO XD | C14: GUION

Sheet H20
A3: N° DE HALLAZGO | B3: 20 | D3: REALIZACION DE LOS AJUSTES
A4: RECURSO | D4: AJUSTE COMPLETO | E4: AJUSTE PARCIAL | F4: NO SE HIZO AJUSTE | G4: OBSERVACIONES
A5: DESCRIPCION DEL HALLAZGO
A6: TIPO DE HALLAZGO
A7: RUTA | D7: REVISION DE LOS AJUSTES
D8: AJUSTE REALIZADO | E8: CON PENDENTES | F8: AJUSTE NO REALIZADO | G8: OBSERVACIONES
A13: EVIDENCIAS
A14: DISEÑO XD | C14: GUION

Sheet H21
A3: N° DE HALLAZGO | B3: 21 | D3: REALIZACION DE LOS AJUSTES
A4: RECURSO | D4: AJUSTE COMPLETO | E4: AJUSTE PARCIAL | F4: NO SE HIZO AJUSTE | G4: OBSERVACIONES
A5: DESCRIPCION DEL HALLAZGO
A6: TIPO DE HALLAZGO
A7: RUTA | D7: REVISION DE LOS AJUSTES
D8: AJUSTE REALIZADO | E8: CON PENDENTES | F8: AJUSTE NO REALIZADO | G8: OBSERVACIONES
A13: EVIDENCIAS
A14: DISEÑO XD | C14: GUION

Sheet H22
A3: N° DE HALLAZGO | B3: 22 | D3: REALIZACION DE LOS AJUSTES
A4: RECURSO | D4: AJUSTE COMPLETO | E4: AJUSTE PARCIAL | F4: NO SE HIZO AJUSTE | G4: OBSERVACIONES
A5: DESCRIPCION DEL HALLAZGO
A6: TIPO DE HALLAZGO
A7: RUTA | D7: REVISION DE LOS AJUSTES
D8: AJUSTE REALIZADO | E8: CON PENDENTES | F8: AJUSTE NO REALIZADO | G8: OBSERVACIONES
A13: EVIDENCIAS
A14: DISEÑO XD | C14: GUION

Sheet H23
A3: N° DE HALLAZGO | B3: 23 | D3: REALIZACION DE LOS AJUSTES
A4: RECURSO | D4: AJUSTE COMPLETO | E4: AJUSTE PARCIAL | F4: NO SE HIZO AJUSTE | G4: OBSERVACIONES
A5: DESCRIPCION DEL HALLAZGO
A6: TIPO DE HALLAZGO
A7: RUTA | D7: REVISION DE LOS AJUSTES
D8: AJUSTE REALIZADO | E8: CON PENDENTES | F8: AJUSTE NO REALIZADO | G8: OBSERVACIONES
A13: EVIDENCIAS
A14: DISEÑO XD | C14: GUION

Sheet H24
A3: N° DE HALLAZGO | B3: 24 | D3: REALIZACION DE LOS AJUSTES
A4: RECURSO | D4: AJUSTE COMPLETO | E4: AJUSTE PARCIAL | F4: NO SE HIZO AJUSTE | G4: OBSERVACIONES
A5: DESCRIPCION DEL HALLAZGO
A6: TIPO DE HALLAZGO
A7: RUTA | D7: REVISION DE LOS AJUSTES
D8: AJUSTE REALIZADO | E8: CON PENDENTES | F8: AJUSTE NO REALIZADO | G8: OBSERVACIONES
A13: EVIDENCIAS
A14: DISEÑO XD | C14: GUION

Sheet H25
A3: N° DE HALLAZGO | B3: 25 | D3: REALIZACION DE LOS AJUSTES
A4: RECURSO | D4: AJUSTE COMPLETO | E4: AJUSTE PARCIAL | F4: NO SE HIZO AJUSTE | G4: OBSERVACIONES
A5: DESCRIPCION DEL HALLAZGO
A6: TIPO DE HALLAZGO
A7: RUTA | D7: REVISION DE LOS AJUSTES
D8: AJUSTE REALIZADO | E8: CON PENDENTES | F8: AJUSTE NO REALIZADO | G8: OBSERVACIONES
A13: EVIDENCIAS
A14: DISEÑO XD | C14: GUION

Sheet H26
A3: N° DE HALLAZGO | B3: 26 | D3: REALIZACION DE LOS AJUSTES
A4: RECURSO | D4: AJUSTE COMPLETO | E4: AJUSTE PARCIAL | F4: NO SE HIZO AJUSTE | G4: OBSERVACIONES
A5: DESCRIPCION DEL HALLAZGO
A6: TIPO DE HALLAZGO
A7: RUTA | D7: REVISION DE LOS AJUSTES
D8: AJUSTE REALIZADO | E8: CON PENDENTES | F8: AJUSTE NO REALIZADO | G8: OBSERVACIONES
A13: EVIDENCIAS
A14: DISEÑO XD | C14: GUION

Sheet H27
A3: N° DE HALLAZGO | B3: 27 | D3: REALIZACION DE LOS AJUSTES
A4: RECURSO | D4: AJUSTE COMPLETO | E4: AJUSTE PARCIAL | F4: NO SE HIZO AJUSTE | G4: OBSERVACIONES
A5: DESCRIPCION DEL HALLAZGO
A6: TIPO DE HALLAZGO
A7: RUTA | D7: REVISION DE LOS AJUSTES
D8: AJUSTE REALIZADO | E8: CON PENDENTES | F8: AJUSTE NO REALIZADO | G8: OBSERVACIONES
A13: EVIDENCIAS
A14: DISEÑO XD | C14: GUION

Sheet H28
A3: N° DE HALLAZGO | B3: 28 | D3: REALIZACION DE LOS AJUSTES
A4: RECURSO | D4: AJUSTE COMPLETO | E4: AJUSTE PARCIAL | F4: NO SE HIZO AJUSTE | G4: OBSERVACIONES
A5: DESCRIPCION DEL HALLAZGO
A6: TIPO DE HALLAZGO
A7: RUTA | D7: REVISION DE LOS AJUSTES
D8: AJUSTE REALIZADO | E8: CON PENDENTES | F8: AJUSTE NO REALIZADO | G8: OBSERVACIONES
A13: EVIDENCIAS
A14: DISEÑO XD | C14: GUION

Sheet H29
A3: N° DE HALLAZGO | B3: 29 | D3: REALIZACION DE LOS AJUSTES
A4: RECURSO | D4: AJUSTE COMPLETO | E4: AJUSTE PARCIAL | F4: NO SE HIZO AJUSTE | G4: OBSERVACIONES
A5: DESCRIPCION DEL HALLAZGO
A6: TIPO DE HALLAZGO
A7: RUTA | D7: REVISION DE LOS AJUSTES
D8: AJUSTE REALIZADO | E8: CON PENDENTES | F8: AJUSTE NO REALIZADO | G8: OBSERVACIONES
A13: EVIDENCIAS
A14: DISEÑO XD | C14: GUION

Sheet H30
A3: N° DE HALLAZGO | B3: 30 | D3: REALIZACION DE LOS AJUSTES
A4: RECURSO | D4: AJUSTE COMPLETO | E4: AJUSTE PARCIAL | F4: NO SE HIZO AJUSTE | G4: OBSERVACIONES
A5: DESCRIPCION DEL HALLAZGO
A6: TIPO DE HALLAZGO
A7: RUTA | D7: REVISION DE LOS AJUSTES
D8: AJUSTE REALIZADO | E8: CON PENDENTES | F8: AJUSTE NO REALIZADO | G8: OBSERVACIONES
A13: EVIDENCIAS
A14: HTML | C14: GUION O XD

Sheet H31
A3: N° DE HALLAZGO | B3: 31 | D3: REALIZACION DE LOS AJUSTES
A4: RECURSO | D4: AJUSTE COMPLETO | E4: AJUSTE PARCIAL | F4: NO SE HIZO AJUSTE | G4: OBSERVACIONES
A5: DESCRIPCION DEL HALLAZGO
A6: TIPO DE HALLAZGO
A7: RUTA | D7: REVISION DE LOS AJUSTES
D8: AJUSTE REALIZADO | E8: CON PENDENTES | F8: AJUSTE NO REALIZADO | G8: OBSERVACIONES
A13: EVIDENCIAS
A14: HTML | C14: GUION O XD

Sheet H32
A3: N° DE HALLAZGO | B3: 32 | D3: REALIZACION DE LOS AJUSTES
A4: RECURSO | D4: AJUSTE COMPLETO | E4: AJUSTE PARCIAL | F4: NO SE HIZO AJUSTE | G4: OBSERVACIONES
A5: DESCRIPCION DEL HALLAZGO
A6: TIPO DE HALLAZGO
A7: RUTA | D7: REVISION DE LOS AJUSTES
D8: AJUSTE REALIZADO | E8: CON PENDENTES | F8: AJUSTE NO REALIZADO | G8: OBSERVACIONES
A13: EVIDENCIAS
A14: HTML | C14: GUION O XD

Sheet H33
A3: N° DE HALLAZGO | B3: 33 | D3: REALIZACION DE LOS AJUSTES
A4: RECURSO | D4: AJUSTE COMPLETO | E4: AJUSTE PARCIAL | F4: NO SE HIZO AJUSTE | G4: OBSERVACIONES
A5: DESCRIPCION DEL HALLAZGO
A6: TIPO DE HALLAZGO
A7: RUTA | D7: REVISION DE LOS AJUSTES
D8: AJUSTE REALIZADO | E8: CON PENDENTES | F8: AJUSTE NO REALIZADO | G8: OBSERVACIONES
A13: EVIDENCIAS
A14: HTML | C14: GUION O XD

Sheet H34
A3: N° DE HALLAZGO | B3: 34 | D3: REALIZACION DE LOS AJUSTES
A4: RECURSO | D4: AJUSTE COMPLETO | E4: AJUSTE PARCIAL | F4: NO SE HIZO AJUSTE | G4: OBSERVACIONES
A5: DESCRIPCION DEL HALLAZGO
A6: TIPO DE HALLAZGO
A7: RUTA | D7: REVISION DE LOS AJUSTES
D8: AJUSTE REALIZADO | E8: CON PENDENTES | F8: AJUSTE NO REALIZADO | G8: OBSERVACIONES
A13: EVIDENCIAS
A14: HTML | C14: GUION O XD

Sheet H35
A3: N° DE HALLAZGO | B3: 35 | D3: REALIZACION DE LOS AJUSTES
A4: RECURSO | D4: AJUSTE COMPLETO | E4: AJUSTE PARCIAL | F4: NO SE HIZO AJUSTE | G4: OBSERVACIONES
A5: DESCRIPCION DEL HALLAZGO
A6: TIPO DE HALLAZGO
A7: RUTA | D7: REVISION DE LOS AJUSTES
D8: AJUSTE REALIZADO | E8: CON PENDENTES | F8: AJUSTE NO REALIZADO | G8: OBSERVACIONES
A13: EVIDENCIAS
A14: HTML | C14: GUION O XD

Sheet H36
A3: N° DE HALLAZGO | B3: 36 | D3: REALIZACION DE LOS AJUSTES
A4: RECURSO | D4: AJUSTE COMPLETO | E4: AJUSTE PARCIAL | F4: NO SE HIZO AJUSTE | G4: OBSERVACIONES
A5: DESCRIPCION DEL HALLAZGO
A6: TIPO DE HALLAZGO
A7: RUTA | D7: REVISION DE LOS AJUSTES
D8: AJUSTE REALIZADO | E8: CON PENDENTES | F8: AJUSTE NO REALIZADO | G8: OBSERVACIONES
A13: EVIDENCIAS
A14: HTML | C14: GUION O XD

Sheet H37
A3: N° DE HALLAZGO | B3: 37 | D3: REALIZACION DE LOS AJUSTES
A4: RECURSO | D4: AJUSTE COMPLETO | E4: AJUSTE PARCIAL | F4: NO SE HIZO AJUSTE | G4: OBSERVACIONES
A5: DESCRIPCION DEL HALLAZGO
A6: TIPO DE HALLAZGO
A7: RUTA | D7: REVISION DE LOS AJUSTES
D8: AJUSTE REALIZADO | E8: CON PENDENTES | F8: AJUSTE NO REALIZADO | G8: OBSERVACIONES
A13: EVIDENCIAS
A14: HTML | C14: GUION O XD

Sheet H38
A3: N° DE HALLAZGO | B3: 38 | D3: REALIZACION DE LOS AJUSTES
A4: RECURSO | D4: AJUSTE COMPLETO | E4: AJUSTE PARCIAL | F4: NO SE HIZO AJUSTE | G4: OBSERVACIONES
A5: DESCRIPCION DEL HALLAZGO
A6: TIPO DE HALLAZGO
A7: RUTA | D7: REVISION DE LOS AJUSTES
D8: AJUSTE REALIZADO | E8: CON PENDENTES | F8: AJUSTE NO REALIZADO | G8: OBSERVACIONES
A13: EVIDENCIAS
A14: HTML | C14: GUION O XD

Sheet H39
A3: N° DE HALLAZGO | B3: 39 | D3: REALIZACION DE LOS AJUSTES
A4: RECURSO | D4: AJUSTE COMPLETO | E4: AJUSTE PARCIAL | F4: NO SE HIZO AJUSTE | G4: OBSERVACIONES
A5: DESCRIPCION DEL HALLAZGO
A6: TIPO DE HALLAZGO
A7: RUTA | D7: REVISION DE LOS AJUSTES
D8: AJUSTE REALIZADO | E8: CON PENDENTES | F8: AJUSTE NO REALIZADO | G8: OBSERVACIONES
A13: EVIDENCIAS
A14: HTML | C14: GUION O XD

Sheet H40
A3: N° DE HALLAZGO | B3: 40 | D3: REALIZACION DE LOS AJUSTES
A4: RECURSO | D4: AJUSTE COMPLETO | E4: AJUSTE PARCIAL | F4: NO SE HIZO AJUSTE | G4: OBSERVACIONES
A5: DESCRIPCION DEL HALLAZGO
A6: TIPO DE HALLAZGO
A7: RUTA | D7: REVISION DE LOS AJUSTES
D8: AJUSTE REALIZADO | E8: CON PENDENTES | F8: AJUSTE NO REALIZADO | G8: OBSERVACIONES
A13: EVIDENCIAS
A14: HTML | C14: GUION O XD

Sheet H41
A3: N° DE HALLAZGO | B3: 41 | D3: REALIZACION DE LOS AJUSTES
A4: RECURSO | D4: AJUSTE COMPLETO | E4: AJUSTE PARCIAL | F4: NO SE HIZO AJUSTE | G4: OBSERVACIONES
A5: DESCRIPCION DEL HALLAZGO
A6: TIPO DE HALLAZGO
A7: RUTA | D7: REVISION DE LOS AJUSTES
D8: AJUSTE REALIZADO | E8: CON PENDENTES | F8: AJUSTE NO REALIZADO | G8: OBSERVACIONES
A13: EVIDENCIAS
A14: HTML | C14: GUION O XD

Sheet H42
A3: N° DE HALLAZGO | B3: 42 | D3: REALIZACION DE LOS AJUSTES
A4: RECURSO | D4: AJUSTE COMPLETO | E4: AJUSTE PARCIAL | F4: NO SE HIZO AJUSTE | G4: OBSERVACIONES
A5: DESCRIPCION DEL HALLAZGO
A6: TIPO DE HALLAZGO
A7: RUTA | D7: REVISION DE LOS AJUSTES
D8: AJUSTE REALIZADO | E8: CON PENDENTES | F8: AJUSTE NO REALIZADO | G8: OBSERVACIONES
A13: EVIDENCIAS
A14: HTML | C14: GUION O XD

Sheet H43
A3: N° DE HALLAZGO | B3: 43 | D3: REALIZACION DE LOS AJUSTES
A4: RECURSO | D4: AJUSTE COMPLETO | E4: AJUSTE PARCIAL | F4: NO SE HIZO AJUSTE | G4: OBSERVACIONES
A5: DESCRIPCION DEL HALLAZGO
A6: TIPO DE HALLAZGO
A7: RUTA | D7: REVISION DE LOS AJUSTES
D8: AJUSTE REALIZADO | E8: CON PENDENTES | F8: AJUSTE NO REALIZADO | G8: OBSERVACIONES
A13: EVIDENCIAS
A14: HTML | C14: GUION O XD

Sheet H44
A3: N° DE HALLAZGO | B3: 44 | D3: REALIZACION DE LOS AJUSTES
A4: RECURSO | D4: AJUSTE COMPLETO | E4: AJUSTE PARCIAL | F4: NO SE HIZO AJUSTE | G4: OBSERVACIONES
A5: DESCRIPCION DEL HALLAZGO
A6: TIPO DE HALLAZGO
A7: RUTA | D7: REVISION DE LOS AJUSTES
D8: AJUSTE REALIZADO | E8: CON PENDENTES | F8: AJUSTE NO REALIZADO | G8: OBSERVACIONES
A13: EVIDENCIAS
A14: HTML | C14: GUION O XD

Sheet H45
A3: N° DE HALLAZGO | B3: 45 | D3: REALIZACION DE LOS AJUSTES
A4: RECURSO | D4: AJUSTE COMPLETO | E4: AJUSTE PARCIAL | F4: NO SE HIZO AJUSTE | G4: OBSERVACIONES
A5: DESCRIPCION DEL HALLAZGO
A6: TIPO DE HALLAZGO
A7: RUTA | D7: REVISION DE LOS AJUSTES
D8: AJUSTE REALIZADO | E8: CON PENDENTES | F8: AJUSTE NO REALIZADO | G8: OBSERVACIONES
A13: EVIDENCIAS
A14: HTML | C14: GUION O XD

Sheet H46
A3: N° DE HALLAZGO | B3: 46 | D3: REALIZACION DE LOS AJUSTES
A4: RECURSO | D4: AJUSTE COMPLETO | E4: AJUSTE PARCIAL | F4: NO SE HIZO AJUSTE | G4: OBSERVACIONES
A5: DESCRIPCION DEL HALLAZGO
A6: TIPO DE HALLAZGO
A7: RUTA | D7: REVISION DE LOS AJUSTES
D8: AJUSTE REALIZADO | E8: CON PENDENTES | F8: AJUSTE NO REALIZADO | G8: OBSERVACIONES
A13: EVIDENCIAS
A14: HTML | C14: GUION O XD

Sheet H47
A3: N° DE HALLAZGO | B3: 47 | D3: REALIZACION DE LOS AJUSTES
A4: RECURSO | D4: AJUSTE COMPLETO | E4: AJUSTE PARCIAL | F4: NO SE HIZO AJUSTE | G4: OBSERVACIONES
A5: DESCRIPCION DEL HALLAZGO
A6: TIPO DE HALLAZGO
A7: RUTA | D7: REVISION DE LOS AJUSTES
D8: AJUSTE REALIZADO | E8: CON PENDENTES | F8: AJUSTE NO REALIZADO | G8: OBSERVACIONES
A13: EVIDENCIAS
A14: HTML | C14: GUION O XD

Sheet H48
A3: N° DE HALLAZGO | B3: 48 | D3: REALIZACION DE LOS AJUSTES
A4: RECURSO | D4: AJUSTE COMPLETO | E4: AJUSTE PARCIAL | F4: NO SE HIZO AJUSTE | G4: OBSERVACIONES
A5: DESCRIPCION DEL HALLAZGO
A6: TIPO DE HALLAZGO
A7: RUTA | D7: REVISION DE LOS AJUSTES
D8: AJUSTE REALIZADO | E8: CON PENDENTES | F8: AJUSTE NO REALIZADO | G8: OBSERVACIONES
A13: EVIDENCIAS
A14: HTML | C14: GUION O XD

Sheet H49
A3: N° DE HALLAZGO | B3: 49 | D3: REALIZACION DE LOS AJUSTES
A4: RECURSO | D4: AJUSTE COMPLETO | E4: AJUSTE PARCIAL | F4: NO SE HIZO AJUSTE | G4: OBSERVACIONES
A5: DESCRIPCION DEL HALLAZGO
A6: TIPO DE HALLAZGO
A7: RUTA | D7: REVISION DE LOS AJUSTES
D8: AJUSTE REALIZADO | E8: CON PENDENTES | F8: AJUSTE NO REALIZADO | G8: OBSERVACIONES
A13: EVIDENCIAS
A14: HTML | C14: GUION O XD

Sheet H50
A3: N° DE HALLAZGO | B3: 50 | D3: REALIZACION DE LOS AJUSTES
A4: RECURSO | D4: AJUSTE COMPLETO | E4: AJUSTE PARCIAL | F4: NO SE HIZO AJUSTE | G4: OBSERVACIONES
A5: DESCRIPCION DEL HALLAZGO
A6: TIPO DE HALLAZGO
A7: RUTA | D7: REVISION DE LOS AJUSTES
D8: AJUSTE REALIZADO | E8: CON PENDENTES | F8: AJUSTE NO REALIZADO | G8: OBSERVACIONES
A13: EVIDENCIAS
A14: HTML | C14: GUION O XD

Sheet H51
A3: N° DE HALLAZGO | B3: 51 | D3: REALIZACION DE LOS AJUSTES
A4: RECURSO | D4: AJUSTE COMPLETO | E4: AJUSTE PARCIAL | F4: NO SE HIZO AJUSTE | G4: OBSERVACIONES
A5: DESCRIPCION DEL HALLAZGO
A6: TIPO DE HALLAZGO
A7: RUTA | D7: REVISION DE LOS AJUSTES
D8: AJUSTE REALIZADO | E8: CON PENDENTES | F8: AJUSTE NO REALIZADO | G8: OBSERVACIONES
A13: EVIDENCIAS
A14: HTML | C14: GUION O XD

Sheet H52
A3: N° DE HALLAZGO | B3: 52 | D3: REALIZACION DE LOS AJUSTES
A4: RECURSO | D4: AJUSTE COMPLETO | E4: AJUSTE PARCIAL | F4: NO SE HIZO AJUSTE | G4: OBSERVACIONES
A5: DESCRIPCION DEL HALLAZGO
A6: TIPO DE HALLAZGO
A7: RUTA | D7: REVISION DE LOS AJUSTES
D8: AJUSTE REALIZADO | E8: CON PENDENTES | F8: AJUSTE NO REALIZADO | G8: OBSERVACIONES
A13: EVIDENCIAS
A14: HTML | C14: GUION O XD

Sheet H53
A3: N° DE HALLAZGO | B3: 53 | D3: REALIZACION DE LOS AJUSTES
A4: RECURSO | D4: AJUSTE COMPLETO | E4: AJUSTE PARCIAL | F4: NO SE HIZO AJUSTE | G4: OBSERVACIONES
A5: DESCRIPCION DEL HALLAZGO
A6: TIPO DE HALLAZGO
A7: RUTA | D7: REVISION DE LOS AJUSTES
D8: AJUSTE REALIZADO | E8: CON PENDENTES | F8: AJUSTE NO REALIZADO | G8: OBSERVACIONES
A13: EVIDENCIAS
A14: HTML | C14: GUION O XD

Sheet H54
A3: N° DE HALLAZGO | B3: 54 | D3: REALIZACION DE LOS AJUSTES
A4: RECURSO | D4: AJUSTE COMPLETO | E4: AJUSTE PARCIAL | F4: NO SE HIZO AJUSTE | G4: OBSERVACIONES
A5: DESCRIPCION DEL HALLAZGO
A6: TIPO DE HALLAZGO
A7: RUTA | D7: REVISION DE LOS AJUSTES
D8: AJUSTE REALIZADO | E8: CON PENDENTES | F8: AJUSTE NO REALIZADO | G8: OBSERVACIONES
A13: EVIDENCIAS
A14: HTML | C14: GUION O XD

Sheet H55
A3: N° DE HALLAZGO | B3: 55 | D3: REALIZACION DE LOS AJUSTES
A4: RECURSO | D4: AJUSTE COMPLETO | E4: AJUSTE PARCIAL | F4: NO SE HIZO AJUSTE | G4: OBSERVACIONES
A5: DESCRIPCION DEL HALLAZGO
A6: TIPO DE HALLAZGO
A7: RUTA | D7: REVISION DE LOS AJUSTES
D8: AJUSTE REALIZADO | E8: CON PENDENTES | F8: AJUSTE NO REALIZADO | G8: OBSERVACIONES
A13: EVIDENCIAS
A14: HTML | C14: GUION O XD

Sheet H56
A3: N° DE HALLAZGO | B3: 56 | D3: REALIZACION DE LOS AJUSTES
A4: RECURSO | D4: AJUSTE COMPLETO | E4: AJUSTE PARCIAL | F4: NO SE HIZO AJUSTE | G4: OBSERVACIONES
A5: DESCRIPCION DEL HALLAZGO
A6: TIPO DE HALLAZGO
A7: RUTA | D7: REVISION DE LOS AJUSTES
D8: AJUSTE REALIZADO | E8: CON PENDENTES | F8: AJUSTE NO REALIZADO | G8: OBSERVACIONES
A13: EVIDENCIAS
A14: HTML | C14: GUION O XD

Sheet H57
A3: N° DE HALLAZGO | B3: 57 | D3: REALIZACION DE LOS AJUSTES
A4: RECURSO | D4: AJUSTE COMPLETO | E4: AJUSTE PARCIAL | F4: NO SE HIZO AJUSTE | G4: OBSERVACIONES
A5: DESCRIPCION DEL HALLAZGO
A6: TIPO DE HALLAZGO
A7: RUTA | D7: REVISION DE LOS AJUSTES
D8: AJUSTE REALIZADO | E8: CON PENDENTES | F8: AJUSTE NO REALIZADO | G8: OBSERVACIONES
A13: EVIDENCIAS
A14: HTML | C14: GUION O XD

Sheet H58
A3: N° DE HALLAZGO | B3: 58 | D3: REALIZACION DE LOS AJUSTES
A4: RECURSO | D4: AJUSTE COMPLETO | E4: AJUSTE PARCIAL | F4: NO SE HIZO AJUSTE | G4: OBSERVACIONES
A5: DESCRIPCION DEL HALLAZGO
A6: TIPO DE HALLAZGO
A7: RUTA | D7: REVISION DE LOS AJUSTES
D8: AJUSTE REALIZADO | E8: CON PENDENTES | F8: AJUSTE NO REALIZADO | G8: OBSERVACIONES
A13: EVIDENCIAS
A14: HTML | C14: GUION O XD

Sheet H59
A3: N° DE HALLAZGO | B3: 59 | D3: REALIZACION DE LOS AJUSTES
A4: RECURSO | D4: AJUSTE COMPLETO | E4: AJUSTE PARCIAL | F4: NO SE HIZO AJUSTE | G4: OBSERVACIONES
A5: DESCRIPCION DEL HALLAZGO
A6: TIPO DE HALLAZGO
A7: RUTA | D7: REVISION DE LOS AJUSTES
D8: AJUSTE REALIZADO | E8: CON PENDENTES | F8: AJUSTE NO REALIZADO | G8: OBSERVACIONES
A13: EVIDENCIAS
A14: HTML | C14: GUION O XD

Sheet H60
A3: N° DE HALLAZGO | B3: 60 | D3: REALIZACION DE LOS AJUSTES
A4: RECURSO | D4: AJUSTE COMPLETO | E4: AJUSTE PARCIAL | F4: NO SE HIZO AJUSTE | G4: OBSERVACIONES
A5: DESCRIPCION DEL HALLAZGO
A6: TIPO DE HALLAZGO
A7: RUTA | D7: REVISION DE LOS AJUSTES
D8: AJUSTE REALIZADO | E8: CON PENDENTES | F8: AJUSTE NO REALIZADO | G8: OBSERVACIONES
A13: EVIDENCIAS
A14: HTML | C14: GUION O XD

Sheet H61
A3: N° DE HALLAZGO | B3: 61 | D3: REALIZACION DE LOS AJUSTES
A4: RECURSO | D4: AJUSTE COMPLETO | E4: AJUSTE PARCIAL | F4: NO SE HIZO AJUSTE | G4: OBSERVACIONES
A5: DESCRIPCION DEL HALLAZGO
A6: TIPO DE HALLAZGO
A7: RUTA | D7: REVISION DE LOS AJUSTES
D8: AJUSTE REALIZADO | E8: CON PENDENTES | F8: AJUSTE NO REALIZADO | G8: OBSERVACIONES
A13: EVIDENCIAS
A14: HTML | C14: GUION O XD

Sheet H62
A3: N° DE HALLAZGO | B3: 62 | D3: REALIZACION DE LOS AJUSTES
A4: RECURSO | D4: AJUSTE COMPLETO | E4: AJUSTE PARCIAL | F4: NO SE HIZO AJUSTE | G4: OBSERVACIONES
A5: DESCRIPCION DEL HALLAZGO
A6: TIPO DE HALLAZGO
A7: RUTA | D7: REVISION DE LOS AJUSTES
D8: AJUSTE REALIZADO | E8: CON PENDENTES | F8: AJUSTE NO REALIZADO | G8: OBSERVACIONES
A13: EVIDENCIAS
A14: HTML | C14: GUION O XD

Sheet H63
A3: N° DE HALLAZGO | B3: 63 | D3: REALIZACION DE LOS AJUSTES
A4: RECURSO | D4: AJUSTE COMPLETO | E4: AJUSTE PARCIAL | F4: NO SE HIZO AJUSTE | G4: OBSERVACIONES
A5: DESCRIPCION DEL HALLAZGO
A6: TIPO DE HALLAZGO
A7: RUTA | D7: REVISION DE LOS AJUSTES
D8: AJUSTE REALIZADO | E8: CON PENDENTES | F8: AJUSTE NO REALIZADO | G8: OBSERVACIONES
A13: EVIDENCIAS
A14: HTML | C14: GUION O XD

Sheet H64
A3: N° DE HALLAZGO | B3: 64 | D3: REALIZACION DE LOS AJUSTES
A4: RECURSO | D4: AJUSTE COMPLETO | E4: AJUSTE PARCIAL | F4: NO SE HIZO AJUSTE | G4: OBSERVACIONES
A5: DESCRIPCION DEL HALLAZGO
A6: TIPO DE HALLAZGO
A7: RUTA | D7: REVISION DE LOS AJUSTES
D8: AJUSTE REALIZADO | E8: CON PENDENTES | F8: AJUSTE NO REALIZADO | G8: OBSERVACIONES
A13: EVIDENCIAS
A14: HTML | C14: GUION O XD

Sheet H65
A3: N° DE HALLAZGO | B3: 65 | D3: REALIZACION DE LOS AJUSTES
A4: RECURSO | D4: AJUSTE COMPLETO | E4: AJUSTE PARCIAL | F4: NO SE HIZO AJUSTE | G4: OBSERVACIONES
A5: DESCRIPCION DEL HALLAZGO
A6: TIPO DE HALLAZGO
A7: RUTA | D7: REVISION DE LOS AJUSTES
D8: AJUSTE REALIZADO | E8: CON PENDENTES | F8: AJUSTE NO REALIZADO | G8: OBSERVACIONES
A13: EVIDENCIAS
A14: HTML | C14: GUION O XD

Sheet H66
A3: N° DE HALLAZGO | B3: 66 | D3: REALIZACION DE LOS AJUSTES
A4: RECURSO | D4: AJUSTE COMPLETO | E4: AJUSTE PARCIAL | F4: NO SE HIZO AJUSTE | G4: OBSERVACIONES
A5: DESCRIPCION DEL HALLAZGO
A6: TIPO DE HALLAZGO
A7: RUTA | D7: REVISION DE LOS AJUSTES
D8: AJUSTE REALIZADO | E8: CON PENDENTES | F8: AJUSTE NO REALIZADO | G8: OBSERVACIONES
A13: EVIDENCIAS
A14: HTML | C14: GUION O XD

Sheet H67
A3: N° DE HALLAZGO | B3: 67 | D3: REALIZACION DE LOS AJUSTES
A4: RECURSO | D4: AJUSTE COMPLETO | E4: AJUSTE PARCIAL | F4: NO SE HIZO AJUSTE | G4: OBSERVACIONES
A5: DESCRIPCION DEL HALLAZGO
A6: TIPO DE HALLAZGO
A7: RUTA | D7: REVISION DE LOS AJUSTES
D8: AJUSTE REALIZADO | E8: CON PENDENTES | F8: AJUSTE NO REALIZADO | G8: OBSERVACIONES
A13: EVIDENCIAS
A14: HTML | C14: GUION O XD

Sheet H68
A3: N° DE HALLAZGO | B3: 68 | D3: REALIZACION DE LOS AJUSTES
A4: RECURSO | D4: AJUSTE COMPLETO | E4: AJUSTE PARCIAL | F4: NO SE HIZO AJUSTE | G4: OBSERVACIONES
A5: DESCRIPCION DEL HALLAZGO
A6: TIPO DE HALLAZGO
A7: RUTA | D7: REVISION DE LOS AJUSTES
D8: AJUSTE REALIZADO | E8: CON PENDENTES | F8: AJUSTE NO REALIZADO | G8: OBSERVACIONES
A13: EVIDENCIAS
A14: HTML | C14: GUION O XD

Sheet H69
A3: N° DE HALLAZGO | B3: 69 | D3: REALIZACION DE LOS AJUSTES
A4: RECURSO | D4: AJUSTE COMPLETO | E4: AJUSTE PARCIAL | F4: NO SE HIZO AJUSTE | G4: OBSERVACIONES
A5: DESCRIPCION DEL HALLAZGO
A6: TIPO DE HALLAZGO
A7: RUTA | D7: REVISION DE LOS AJUSTES
D8: AJUSTE REALIZADO | E8: CON PENDENTES | F8: AJUSTE NO REALIZADO | G8: OBSERVACIONES
A13: EVIDENCIAS
A14: HTML | C14: GUION O XD

Sheet H70
A3: N° DE HALLAZGO | B3: 70 | D3: REALIZACION DE LOS AJUSTES
A4: RECURSO | D4: AJUSTE COMPLETO | E4: AJUSTE PARCIAL | F4: NO SE HIZO AJUSTE | G4: OBSERVACIONES
A5: DESCRIPCION DEL HALLAZGO
A6: TIPO DE HALLAZGO
A7: RUTA | D7: REVISION DE LOS AJUSTES
D8: AJUSTE REALIZADO | E8: CON PENDENTES | F8: AJUSTE NO REALIZADO | G8: OBSERVACIONES
A13: EVIDENCIAS
A14: HTML | C14: GUION O XD

Sheet H71
A3: N° DE HALLAZGO | B3: 71 | D3: REALIZACION DE LOS AJUSTES
A4: RECURSO | D4: AJUSTE COMPLETO | E4: AJUSTE PARCIAL | F4: NO SE HIZO AJUSTE | G4: OBSERVACIONES
A5: DESCRIPCION DEL HALLAZGO
A6: TIPO DE HALLAZGO
A7: RUTA | D7: REVISION DE LOS AJUSTES
D8: AJUSTE REALIZADO | E8: CON PENDENTES | F8: AJUSTE NO REALIZADO | G8: OBSERVACIONES
A13: EVIDENCIAS
A14: HTML | C14: GUION O XD

Sheet H72
A3: N° DE HALLAZGO | B3: 72 | D3: REALIZACION DE LOS AJUSTES
A4: RECURSO | D4: AJUSTE COMPLETO | E4: AJUSTE PARCIAL | F4: NO SE HIZO AJUSTE | G4: OBSERVACIONES
A5: DESCRIPCION DEL HALLAZGO
A6: TIPO DE HALLAZGO
A7: RUTA | D7: REVISION DE LOS AJUSTES
D8: AJUSTE REALIZADO | E8: CON PENDENTES | F8: AJUSTE NO REALIZADO | G8: OBSERVACIONES
A13: EVIDENCIAS
A14: HTML | C14: GUION O XD

Sheet H73
A3: N° DE HALLAZGO | B3: 73 | D3: REALIZACION DE LOS AJUSTES
A4: RECURSO | D4: AJUSTE COMPLETO | E4: AJUSTE PARCIAL | F4: NO SE HIZO AJUSTE | G4: OBSERVACIONES
A5: DESCRIPCION DEL HALLAZGO
A6: TIPO DE HALLAZGO
A7: RUTA | D7: REVISION DE LOS AJUSTES
D8: AJUSTE REALIZADO | E8: CON PENDENTES | F8: AJUSTE NO REALIZADO | G8: OBSERVACIONES
A13: EVIDENCIAS
A14: HTML | C14: GUION O XD

Sheet H74
A3: N° DE HALLAZGO | B3: 74 | D3: REALIZACION DE LOS AJUSTES
A4: RECURSO | D4: AJUSTE COMPLETO | E4: AJUSTE PARCIAL | F4: NO SE HIZO AJUSTE | G4: OBSERVACIONES
A5: DESCRIPCION DEL HALLAZGO
A6: TIPO DE HALLAZGO
A7: RUTA | D7: REVISION DE LOS AJUSTES
D8: AJUSTE REALIZADO | E8: CON PENDENTES | F8: AJUSTE NO REALIZADO | G8: OBSERVACIONES
A13: EVIDENCIAS
A14: HTML | C14: GUION O XD

Sheet H75
A3: N° DE HALLAZGO | B3: 75 | D3: REALIZACION DE LOS AJUSTES
A4: RECURSO | D4: AJUSTE COMPLETO | E4: AJUSTE PARCIAL | F4: NO SE HIZO AJUSTE | G4: OBSERVACIONES
A5: DESCRIPCION DEL HALLAZGO
A6: TIPO DE HALLAZGO
A7: RUTA | D7: REVISION DE LOS AJUSTES
D8: AJUSTE REALIZADO | E8: CON PENDENTES | F8: AJUSTE NO REALIZADO | G8: OBSERVACIONES
A13: EVIDENCIAS
A14: HTML | C14: GUION O XD

Sheet H76
A3: N° DE HALLAZGO | B3: 76 | D3: REALIZACION DE LOS AJUSTES
A4: RECURSO | D4: AJUSTE COMPLETO | E4: AJUSTE PARCIAL | F4: NO SE HIZO AJUSTE | G4: OBSERVACIONES
A5: DESCRIPCION DEL HALLAZGO
A6: TIPO DE HALLAZGO
A7: RUTA | D7: REVISION DE LOS AJUSTES
D8: AJUSTE REALIZADO | E8: CON PENDENTES | F8: AJUSTE NO REALIZADO | G8: OBSERVACIONES
A13: EVIDENCIAS
A14: HTML | C14: GUION O XD

Sheet H77
A3: N° DE HALLAZGO | B3: 77 | D3: REALIZACION DE LOS AJUSTES
A4: RECURSO | D4: AJUSTE COMPLETO | E4: AJUSTE PARCIAL | F4: NO SE HIZO AJUSTE | G4: OBSERVACIONES
A5: DESCRIPCION DEL HALLAZGO
A6: TIPO DE HALLAZGO
A7: RUTA | D7: REVISION DE LOS AJUSTES
D8: AJUSTE REALIZADO | E8: CON PENDENTES | F8: AJUSTE NO REALIZADO | G8: OBSERVACIONES
A13: EVIDENCIAS
A14: HTML | C14: GUION O XD

Sheet H78
A3: N° DE HALLAZGO | B3: 78 | D3: REALIZACION DE LOS AJUSTES
A4: RECURSO | D4: AJUSTE COMPLETO | E4: AJUSTE PARCIAL | F4: NO SE HIZO AJUSTE | G4: OBSERVACIONES
A5: DESCRIPCION DEL HALLAZGO
A6: TIPO DE HALLAZGO
A7: RUTA | D7: REVISION DE LOS AJUSTES
D8: AJUSTE REALIZADO | E8: CON PENDENTES | F8: AJUSTE NO REALIZADO | G8: OBSERVACIONES
A13: EVIDENCIAS
A14: HTML | C14: GUION O XD

Sheet H79
A3: N° DE HALLAZGO | B3: 79 | D3: REALIZACION DE LOS AJUSTES
A4: RECURSO | D4: AJUSTE COMPLETO | E4: AJUSTE PARCIAL | F4: NO SE HIZO AJUSTE | G4: OBSERVACIONES
A5: DESCRIPCION DEL HALLAZGO
A6: TIPO DE HALLAZGO
A7: RUTA | D7: REVISION DE LOS AJUSTES
D8: AJUSTE REALIZADO | E8: CON PENDENTES | F8: AJUSTE NO REALIZADO | G8: OBSERVACIONES
A13: EVIDENCIAS
A14: HTML | C14: GUION O XD

Sheet H80
A3: N° DE HALLAZGO | B3: 80 | D3: REALIZACION DE LOS AJUSTES
A4: RECURSO | D4: AJUSTE COMPLETO | E4: AJUSTE PARCIAL | F4: NO SE HIZO AJUSTE | G4: OBSERVACIONES
A5: DESCRIPCION DEL HALLAZGO
A6: TIPO DE HALLAZGO
A7: RUTA | D7: REVISION DE LOS AJUSTES
D8: AJUSTE REALIZADO | E8: CON PENDENTES | F8: AJUSTE NO REALIZADO | G8: OBSERVACIONES
A13: EVIDENCIAS
A14: HTML | C14: GUION O XD
